Workbook

Sheet Controle de Validade
A1: Material | B1: UMB | C1: Texto breve de material | D1: Fornecedor (fórmula) | E1: Origem (fórmula) | F1: Responsável (fórmula) | G1: Familia (fórmula) | H1: Controle de validade | I1: Tempo de Validade | J1: Certificados/Laudos | K1: Input | L1: Flag | M1: Validade2 | N1: Comentario
A2: 212.336 | B2: PC | C2: BASE KIT CIRURG COMP HELIX HEXAGONO EXT | D2: INDUSBELLO INDUSTRIA E COMERCIO DE | E2: Nacional | F2: Rafael | G2: ESTOJOS | H2: Sim | I2: 5 Anos | J2: Val.Indusbello | K2: 1 | L2: ✔️ | M2: =INDEX(Validade!H:H,MATCH('Controle de Validade'!A2,Validade!C:C,0)) -> 47261
A3: 212.328 | B3: PC | C3: FUNDO ESTOJO NGS GM | D3: INDUSBELLO INDUSTRIA E COMERCIO DE | E3: Nacional | F3: Rafael | G3: ESTOJOS | H3: Sim | I3: 5 Anos | J3: Val.Indusbello | K3: 1 | L3: ✔️ | M3: =INDEX(Validade!H:H,MATCH('Controle de Validade'!A3,Validade!C:C,0)) -> 47233
A4: 212.321 | B4: PC | C4: BASE EST.PROTETICO GM | D4: INDUSBELLO INDUSTRIA E COMERCIO DE | E4: Nacional | F4: Rafael | G4: ESTOJOS | H4: Sim | I4: 5 Anos | J4: Val.Indusbello | K4: 1 | L4: ✔️ | M4: =INDEX(Validade!H:H,MATCH('Controle de Validade'!A4,Validade!C:C,0)) -> 47314
A5: 212.320 | B5: PC | C5: BASE EST.CIRURG.NGS GM IMP.CON. | D5: INDUSBELLO INDUSTRIA E COMERCIO DE | E5: Nacional | F5: Rafael | G5: ESTOJOS | H5: Sim | I5: 5 Anos | J5: Val.Indusbello | K5: 1 | L5: ✔️ | M5: =INDEX(Validade!H:H,MATCH('Controle de Validade'!A5,Validade!C:C,0)) -> 47163
A6: 212.275 | B6: PC | C6: BASE ESTOJO PROTETICO | D6: INDUSBELLO INDUSTRIA E COMERCIO DE | E6: Nacional | F6: Rafael | G6: ESTOJOS | H6: Sim | I6: 5 Anos | J6: Val.Indusbello | K6: 1 | L6: ✔️ | M6: =INDEX(Validade!H:H,MATCH('Controle de Validade'!A6,Validade!C:C,0)) -> 47062
A7: 212.192 | B7: PC | C7: O-RING PA11 PARA ATTACHMENT EQUATOR ROSA | D7: RHEIN 83 SRL | E7: Importado | F7: Rafael | G7: COMPONENTE NÃO METÁLICO | H7: Não | I7: NA | J7: NA | K7: 0 | L7: ✔️ | M7: =INDEX(Validade!H:H,MATCH('Controle de Validade'!A7,Validade!C:C,0)) -> 0
A8: 212.179 | B8: PC | C8: SUP.CATRACA/SONDA KIT CIRUR.SILICON.INJ. | D8: ALMEIDA E WERNECK LTDA | E8: Nacional | F8: Alexandra | G8: COMPONENTE NÃO METÁLICO | H8: Sim | I8: 1 Ano | J8: Val.Almeida | K8: 1 | L8: ✔️ | M8: =INDEX(Validade!H:H,MATCH('Controle de Validade'!A8,Validade!C:C,0)) -> 45785
A9: 212.124 | B9: PC | C9: O-RING PA11 PARA ATTACHMENT BOLA ROSA | D9: RHEIN 83 SRL | E9: Importado | F9: Rafael | G9: COMPONENTE NÃO METÁLICO | H9: Não | I9: NA | J9: NA | K9: 0 | L9: ✔️ | M9: =INDEX(Validade!H:H,MATCH('Controle de Validade'!A9,Validade!C:C,0)) -> 0
A10: 212.104 | B10: PC | C10: CURETTE SINIO (#1) LONG ALUMINIUM HANDLE | D10: A TITAN | E10: Importado | F10: Rafael | G10: SEMI ACABADOS | H10: Não | I10: NA | J10: NA | K10: 0 | L10: ✔️ | M10: =INDEX(Validade!H:H,MATCH('Controle de Validade'!A10,Validade!C:C,0)) -> 0
A11: 212.092 | B11: PC | C11: FUNDO EST.PROT./OSTEOT. | D11: INDUSBELLO INDUSTRIA E COMERCIO DE | E11: Nacional | F11: Rafael | G11: ESTOJOS | H11: Sim | I11: 5 Anos | J11: Val.Indusbello | K11: 1 | L11: ✔️ | M11: =INDEX(Validade!H:H,MATCH('Controle de Validade'!A11,Validade!C:C,0)) -> 47077
A12: 212.087 | B12: PC | C12: BASE ESTOJO COMPLEMENTO | D12: INDUSBELLO INDUSTRIA E COMERCIO DE | E12: Nacional | F12: Rafael | G12: ESTOJOS | H12: Sim | I12: 5 Anos | J12: Val.Indusbello | K12: 1 | L12: ✔️ | M12: =INDEX(Validade!H:H,MATCH('Controle de Validade'!A12,Validade!C:C,0)) -> 47141
A13: 212.023 | B13: PC | C13: INJETADO PA440 P/ DISCO DE PROTECAO | D13: RHEIN 83 SRL | E13: Importado | F13: Rafael | G13: COMPONENTE NÃO METÁLICO | H13: Não | I13: NA | J13: NA | K13: 0 | L13: ✔️ | M13: =INDEX(Validade!H:H,MATCH('Controle de Validade'!A13,Validade!C:C,0)) -> 0
... A25: 212.126 | B25: PC | C25: O-RING SILICONE D2.16XD0.88MM VERMELHO | D25: PRESSURE SEALS INC | E25: Importado | F25: Rafael | G25: COMPONENTE NÃO METÁLICO | H25: Não | I25: NA | J25: NA | K25: 0 | L25: ✔️ | M25: =INDEX(Validade!H:H,MATCH('Controle de Validade'!A25,Validade!C:C,0)) -> 0
A26: 212.042 | B26: PC | C26: SUPORTE D4.5 SILICONE INJETADO | D26: PERFITECNICA PERFIS TECNICOS DE BOR | E26: Nacional | F26: Alexandra | G26: COMPONENTE NÃO METÁLICO | H26: Sim | I26: 5 Anos | J26: NA | K26: 1 | L26: ✔️ | M26: =INDEX(Validade!H:H,MATCH('Controle de Validade'!A26,Validade!C:C,0)) -> 62458 | N26: Validade 5ANOS
A27: 702996 | B27: PC | C27: TINTA BERLAPRINT AMARELA PANTONE 136C | D27: BERLAC AG | E27: Importado | F27: Gabriela | G27: TINTAS | H27: Sim | K27: 1 | L27: ✔️ | M27: =INDEX(Validade!H:H,MATCH('Controle de Validade'!A27,Validade!C:C,0)) -> 45777 | N27: Precisa dos lotes de cada item
A28: 215.012 | B28: G | C28: TINTA BERLAPRINT MARROM PANTONE 153C | D28: BERLAC AG | E28: Importado | F28: Gabriela | G28: TINTAS | H28: Sim | K28: 1 | L28: ✔️ | M28: =INDEX(Validade!H:H,MATCH('Controle de Validade'!A28,Validade!C:C,0)) -> 45777 | N28: Precisa dos lotes de cada item
A29: 517.005 | B29: PC | C29: ESCOVA EM REGUA DE PP E CERDAS DE NYLON | D29: FABRICA DE ESCOVAS TATUAPE LTDA | E29: Nacional | F29: Rafael | G29: INDIRETO | H29: Não | I29: NA | J29: NA | K29: 1 | L29: ✔️ | M29: =INDEX(Validade!H:H,MATCH('Controle de Validade'!A29,Validade!C:C,0)) -> #N/A | N29: Tmp.valid.restante 1
A30: 512.021 | B30: PC | C30: BICO CERAMICA GUYSON (TRATAM SUPERFICIE) | D30: GUYSON CORPORATION OF USA | E30: Importado | F30: Rafael | G30: INDIRETO | H30: Não | I30: NA | J30: NA | K30: 1 | L30: ✔️ | M30: =INDEX(Validade!H:H,MATCH('Controle de Validade'!A30,Validade!C:C,0)) -> #N/A | N30: Tmp.valid.restante 1
A31: 510.065 | B31: PC | C31: LAMPADA XENOPHOT 64634 HLX EFR 15V 150W | D31: AVATAR MARQUES ZAHDI 07321493989 | E31: Nacional | F31: Rafael | G31: INDIRETO | H31: Não | I31: NA | J31: NA | K31: 1 | L31: ✔️ | M31: =INDEX(Validade!H:H,MATCH('Controle de Validade'!A31,Validade!C:C,0)) -> #N/A | N31: Tmp.valid.restante 1
A32: 504.042 | B32: PC | C32: SAPATILHAS DE PROTECAO | D32: VICTORIA REGIA COMERCIO DE | E32: Nacional | F32: Alexandra | G32: EPI | H32: Sim | I32: 3 Anos | J32: Val.Victoria | K32: 1 | L32: ✔️ | M32: =INDEX(Validade!H:H,MATCH('Controle de Validade'!A32,Validade!C:C,0)) -> 46507 | N32: Tmp.valid.restante 1
A33: 504.032 | B33: PC | C33: MASCARA CIRURGICA DESCARTAVEL | D33: VICTORIA REGIA COMERCIO DE | E33: Nacional | F33: Alexandra | G33: EPI | H33: Sim | I33: 2 Anos | J33: Val.Victoria | K33: 1 | L33: ✔️ | M33: =INDEX(Validade!H:H,MATCH('Controle de Validade'!A33,Validade!C:C,0)) -> 47394
A34: 312.150 | B34: PC | C34: UNIDADE LOGISTICA MASTER C.N. | D34: CARTOSUL FABRICAÇÃO DE ARTEFATOS | E34: Nacional | F34: Rafael | G34: CAIXAS | H34: Não | I34: NA | J34: NA | K34: 0 | L34: ✖️ | M34: =INDEX(Validade!H:H,MATCH('Controle de Validade'!A34,Validade!C:C,0)) -> #N/A
A35: 312.145 | B35: PC | C35: EMBALAGEM TRANSPORTE NIVEL I 439X393X176 | D35: CARTOSUL FABRICAÇÃO DE ARTEFATOS | E35: Nacional | F35: Rafael | G35: CAIXAS | H35: Não | I35: NA | J35: NA | K35: 0 | L35: ✖️ | M35: =INDEX(Validade!H:H,MATCH('Controle de Validade'!A35,Validade!C:C,0)) -> #N/A
A36: 312.043 | B36: PC | C36: SACO ZIPER- GG - 30 ALT x 40 LAR C/ 100 | D36: MERCADO COMERCIO DE EMBALAGENS LTDA | E36: Nacional | F36: Alexandra | G36: SACO PLÁSTICO | H36: Não | I36: NA | J36: NA | K36: 0 | L36: ✖️ | M36: =INDEX(Validade!H:H,MATCH('Controle de Validade'!A36,Validade!C:C,0)) -> #N/A
A37: 204.101 | B37: KG | C37: TENOPOM B3MF TER-INJ(POLI.)POM(PETROPOL) | D37: PETROPOL INDUSTRIA E COMERCIO DE | E37: Nacional | F37: Alexandra | G37: POLÍMEROS INJETADOS | H37: Não | I37: NA | J37: NA | K37: 1 | L37: ✔️ | M37: =INDEX(Validade!H:H,MATCH('Controle de Validade'!A37,Validade!C:C,0)) -> 49188
A38: 803.024 | B38: PC | C38: PAPEL WIPER 23X23 | D38: CONCORDE LOGISTICA & DISTRIBUI | E38: Nacional | F38: Alexandra | G38: LIMPEZA | H38: Não | I38: NA | J38: NA | K38: 0 | L38: ✖️ | M38: =INDEX(Validade!H:H,MATCH('Controle de Validade'!A38,Validade!C:C,0)) -> #N/A
A39: 335.444 | B39: PC | C39: ETIQUETA ENCINTADORA | D39: IMPRIME INDUSTRIA E COMERCIO DE | E39: Nacional | F39: Alexandra | G39: ETIQUETAS | H39: Sim | I39: 1 Ano | J39: Val.Imprime | K39: 1 | L39: ✔️ | M39: =INDEX(Validade!H:H,MATCH('Controle de Validade'!A39,Validade!C:C,0)) -> 45899
A40: 312.089 | B40: PC | C40: CAIXA PAPELAO 60x40x40 PAR FOLHA DUP EST | D40: CARTOSUL FABRICAÇÃO DE ARTEFATOS | E40: Nacional | F40: Rafael | G40: CAIXAS | H40: Não | I40: NA | J40: NA | K40: 0 | L40: ✖️ | M40: =INDEX(Validade!H:H,MATCH('Controle de Validade'!A40,Validade!C:C,0)) -> #N/A
A41: 204.214 | B41: KG | C41: LT1220P01 PC-POLICARBONATO TERMO-INJ. | D41: APTA INDUSTRIA E COMERCIO DE | E41: Nacional | F41: Alexandra | G41: POLÍMEROS INJETADOS | H41: Não | I41: NA | J41: NA | K41: 0 | L41: ✔️ | M41: =INDEX(Validade!H:H,MATCH('Controle de Validade'!A41,Validade!C:C,0)) -> 62458
A42: 204.143 | B42: MM | C42: PEEK POLI-ETER-ETER-CETONA D6MM NATURAL | D42: ENSINGER INDUSTRIA DE PLASTICOS | E42: Nacional | F42: Rafael | G42: POLÍMEROS USINADOS | H42: Não | I42: NA | J42: NA | K42: 0 | L42: ✔️ | M42: =INDEX(Validade!H:H,MATCH('Controle de Validade'!A42,Validade!C:C,0)) -> 62458
A43: 703975 | B43: KG | C43: OXIDO DE ALUMINIO ALR 120 ANSI | D43: ELFUSA GERAL DE ELETROFUSAO LTDA. | E43: Nacional | F43: Rafael | G43: INDIRETO | H43: Não | I43: NA | J43: NA | K43: 0 | L43: ✔️ | M43: =INDEX(Validade!H:H,MATCH('Controle de Validade'!A43,Validade!C:C,0)) -> 62458
A44: 702997 | B44: PC | C44: TINTA BERLAPRINT CORAL PANTONE 7416C | D44: BERLAC AG | E44: Importado | F44: Gabriela | G44: TINTAS | H44: Sim | K44: 1 | L44: ✔️ | M44: =INDEX(Validade!H:H,MATCH('Controle de Validade'!A44,Validade!C:C,0)) -> 45716 | N44: Precisa dos lotes de cada item
A45: 702934 | B45: PC | C45: ACO RAPIDO M2 3,17X32,00MM | D45: DIAMANPAR INDUSTRIA E COMERCIO DE | E45: Nacional | F45: Gabriela | G45: AÇO NACIONAL | H45: Não | I45: NA | J45: NA | K45: 0 | L45: ✔️ | M45: =INDEX(Validade!H:H,MATCH('Controle de Validade'!A45,Validade!C:C,0)) -> 62458
A46: 302.055 | B46: PC | C46: EMB. CART. IMPLANTE TITAMAX TI EX | D46: KEOPS INDUSTRIA GRAFICA S.A. | E46: Nacional | F46: Rafael | G46: PHASE OUT | H46: Não | I46: NA | J46: NA | K46: 0 | L46: ✔️ | M46: =INDEX(Validade!H:H,MATCH('Controle de Validade'!A46,Validade!C:C,0)) -> 62458
A47: 120.075 | B47: PC | C47: MAXILA PARA HANDS ON CIRURGIA GUIADA | D47: ORBITAL BONE | E47: Nacional | F47: Gabriela | G47: CURSOS / MKT | H47: Não | I47: NA | J47: NA | K47: 1 | L47: ✔️ | M47: =INDEX(Validade!H:H,MATCH('Controle de Validade'!A47,Validade!C:C,0)) -> 62458 | N47: Tmp.valid.restante 1
A48: 120.081 | B48: PC | C48: MODULO FLUXO PROTETICO GM | D48: QUALIFILME EMBALAGENS LTDA | E48: Nacional | F48: Gabriela | G48: CURSOS / MKT | H48: Não | I48: NA | J48: NA | K48: 0 | L48: ✔️ | M48: =INDEX(Validade!H:H,MATCH('Controle de Validade'!A48,Validade!C:C,0)) -> 62458
A49: 120.084 | B49: PC | C49: ZI BLOCO OSSEO DE 2 DENSIDADES | D49: FRANCESCHI & COSTA E SILVA LTDA | E49: Nacional | F49: Gabriela | G49: CURSOS / MKT | H49: Não | I49: NA | J49: NA | K49: 0 | L49: ✔️ | M49: =INDEX(Validade!H:H,MATCH('Controle de Validade'!A49,Validade!C:C,0)) -> 0
A50: 131.330 | B50: PC | C50: Demo Maxila Parcial. Desd-Neoarch, Poly | D50: FRANCESCHI & COSTA E SILVA LTDA | E50: Nacional | F50: Gabriela | G50: CURSOS / MKT | H50: Não | I50: NA | J50: NA | K50: 1 | L50: ✔️ | M50: =INDEX(Validade!H:H,MATCH('Controle de Validade'!A50,Validade!C:C,0)) -> 62458 | N50: Tmp.valid.restante 1
A51: 317324 | B51: PC | C51: CPO CONEXAO AS PARA CONTRA ANGULO | D51: Institut Straumann SA | E51: Internacional | F51: Rafael | G51: SEMI ACABADOS | H51: Não | I51: NA | J51: NA | K51: 0 | L51: ✔️ | M51: =INDEX(Validade!H:H,MATCH('Controle de Validade'!A51,Validade!C:C,0)) -> 0
...

Sheet Responsável
A1: Material | B1: Cód fornecedor | C1: Fornecedor | D1: Novo planejador | E1: Origem | F1: Frequencia de entrega | G1: Política | H1: Base de Cálculo | I1: FAMÍLIA | J1: Família Processo | K1: Comentário | L1: Antigo Responsável | M1: Precisa informar?
A2: 805.036 | B2: 44000491 | C2: 3Z FITABRAS FITAS E ABRASIVOS | D2: Alexandra | E2: Nacional | F2: 60 | G2: 30 | H2: Consumo médio | I2: FITAS | J2: PRODUÇÃO | L2: Rafael | M2: =L2=D2 -> FALSE
A3: 019.0703 | D3: Gabriela | E3: Importado | F3: 0 | G3: 0 | H3: Maior entre | I3: EM DESENVOLVIMENTO | J3: EM DESENVOLVIMENTO | K3: Paloma verificando com o Thiago Riberto para atualizar as infos do item. | L3: Gabriela | M3: =L3=D3 -> TRUE
A4: 083.515 | D4: Gabriela | E4: Importado | F4: 0 | G4: 0 | H4: Maior entre | I4: EM DESENVOLVIMENTO | J4: EM DESENVOLVIMENTO | K4: Compra solicitada pela Erika Nascimento, para teste | L4: Gabriela | M4: =L4=D4 -> TRUE
A5: 201.011 | B5: 40004588 | C5: DYNAMET INC | D5: Gabriela | E5: Importado | F5: 30 | G5: 900 | H5: Plano de Produção | I5: TITÂNIO | J5: PROD USINAGEM | L5: Gabriela | M5: =L5=D5 -> TRUE
A6: 201.011 | B6: 40004587 | C6: Perryman Company | D6: Gabriela | E6: Importado | F6: 30 | G6: 900 | H6: Plano de Produção | I6: TITÂNIO | J6: PROD USINAGEM | L6: Gabriela | M6: =L6=D6 -> TRUE
A7: 201.012 | B7: 40004588 | C7: DYNAMET INC | D7: Gabriela | E7: Importado | F7: 30 | G7: 900 | H7: Plano de Produção | I7: TITÂNIO | J7: PROD USINAGEM | L7: Gabriela | M7: =L7=D7 -> TRUE
A8: 204.247 | B8: 44002381 | C8: ACNIS DO BRASIL COMERCIO DE | D8: Rafael | E8: Nacional | F8: 30 | G8: 120 | H8: Plano de Produção | I8: POLÍMEROS USINADOS | J8: VERIFCAR ONDE É USADO | L8: Rafael | M8: =L8=D8 -> TRUE
A9: 204.246 | B9: 44002381 | C9: ACNIS DO BRASIL COMERCIO DE | D9: Rafael | E9: Nacional | F9: 30 | G9: 120 | H9: Plano de Produção | I9: POLÍMEROS USINADOS | J9: VERIFCAR ONDE É USADO | L9: Rafael | M9: =L9=D9 -> TRUE
A10: 202.148 | B10: 44002356 | C10: ACOS BOHLER - UDDEHOLM DO BRASIL | D10: Gabriela | E10: Nacional | F10: 30 | G10: 900 | H10: Plano de Produção | I10: AÇO IMPORTADO | J10: PROD USINAGEM | L10: Gabriela | M10: =L10=D10 -> TRUE
A11: 202.146 | B11: 44002356 | C11: ACOS BOHLER - UDDEHOLM DO BRASIL | D11: Gabriela | E11: Nacional | F11: 30 | G11: 900 | H11: Plano de Produção | I11: AÇO IMPORTADO | J11: PROD USINAGEM | K11: Material em esgotamento, considerar política 0 | L11: Gabriela | M11: =L11=D11 -> TRUE
A12: 202.148 | B12: 44006500 | C12: ACOS BOHLER-UDDEHOLM DO BRASIL LTDA | D12: Gabriela | E12: Nacional | F12: 30 | G12: 900 | H12: Plano de Produção | I12: AÇO IMPORTADO | J12: PROD USINAGEM | L12: Gabriela | M12: =L12=D12 -> TRUE
A13: 204.099 | B13: 44005666 | C13: ACTIVAS PLASTICOS INDUSTRIAIS LTDA | D13: Alexandra | E13: Nacional | F13: 15 | G13: 90 | H13: Plano de Produção | I13: POLÍMEROS INJETADOS | J13: PROD INJETORA | L13: Rafael | M13: =L13=D13 -> FALSE
A14: 704672 | B14: 44006329 | C14: ADITEK DO BRASIL LTDA | D14: Rafael | E14: Nacional | F14: 30 | H14: Consumo médio | I14: SMILINK | J14: PROD CLEAR | L14: Gabriela | M14: =L14=D14 -> FALSE
A15: 01.05.0001.9 | B15: 44006329 | C15: ADITEK DO BRASIL LTDA | D15: Rafael | E15: Nacional | F15: 30 | H15: Consumo médio | I15: SMILINK | J15: PROD CLEAR | L15: Gabriela | M15: =L15=D15 -> FALSE
A16: 801.034 | B16: 44003250 | C16: ALEGRAF GRAFICA E EDITORA - ME | D16: Rafael | E16: Nacional | F16: 30 | G16: 60 | H16: NA | I16: PHASE OUT | J16: DIVERSOS | K16: Cada setor comprará o seu | L16: Rafael | M16: =L16=D16 -> TRUE
A17: 704269 | B17: 44003250 | C17: ALEGRAF GRAFICA E EDITORA - ME | D17: Rafael | E17: Nacional | F17: 30 | G17: 0 | H17: NA | I17: PHASE OUT | K17: phase out | L17: Rafael | M17: =L17=D17 -> TRUE
A18: 703101 | B18: 44003250 | C18: ALEGRAF GRAFICA E EDITORA - ME | D18: Rafael | E18: Nacional | G18: 0 | H18: NA | I18: PHASE OUT | J18: PROD CLEAR | K18: Mudança de projeto, entrada do Rebranding | L18: Rafael | M18: =L18=D18 -> TRUE
A19: 705642 | B19: 44000002 | C19: ALMEIDA E WERNECK LTDA | D19: Alexandra | E19: Nacional | F19: 30 | G19: 45 | H19: Plano de Produção | I19: COMPONENTE NÃO METÁLICO | J19: PROD MONTAGEM | L19: Rafael | M19: =L19=D19 -> FALSE
A20: 705641 | B20: 44000002 | C20: ALMEIDA E WERNECK LTDA | D20: Alexandra | E20: Nacional | F20: 30 | G20: 45 | H20: Plano de Produção | I20: COMPONENTE NÃO METÁLICO | J20: PROD MONTAGEM | L20: Rafael | M20: =L20=D20 -> FALSE
A21: 705640 | B21: 44000002 | C21: ALMEIDA E WERNECK LTDA | D21: Alexandra | E21: Nacional | F21: 30 | G21: 45 | H21: Plano de Produção | I21: COMPONENTE NÃO METÁLICO | J21: PROD MONTAGEM | L21: Rafael | M21: =L21=D21 -> FALSE
A22: 705639 | B22: 44000002 | C22: ALMEIDA E WERNECK LTDA | D22: Alexandra | E22: Nacional | F22: 30 | G22: 45 | H22: Plano de Produção | I22: COMPONENTE NÃO METÁLICO | J22: PROD MONTAGEM | L22: Rafael | M22: =L22=D22 -> FALSE
A23: 705638 | B23: 44000002 | C23: ALMEIDA E WERNECK LTDA | D23: Alexandra | E23: Nacional | F23: 30 | G23: 45 | H23: Plano de Produção | I23: COMPONENTE NÃO METÁLICO | J23: PROD MONTAGEM | L23: Rafael | M23: =L23=D23 -> FALSE
A24: 705637 | B24: 44000002 | C24: ALMEIDA E WERNECK LTDA | D24: Alexandra | E24: Nacional | F24: 30 | G24: 45 | H24: Plano de Produção | I24: COMPONENTE NÃO METÁLICO | J24: PROD MONTAGEM | L24: Rafael | M24: =L24=D24 -> FALSE
A25: 705636 | B25: 44000002 | C25: ALMEIDA E WERNECK LTDA | D25: Alexandra | E25: Nacional | F25: 30 | G25: 45 | H25: Plano de Produção | I25: COMPONENTE NÃO METÁLICO | J25: PROD MONTAGEM | L25: Rafael | M25: =L25=D25 -> FALSE
A26: 704348 | B26: 44000002 | C26: ALMEIDA E WERNECK LTDA | D26: Alexandra | E26: Nacional | F26: 30 | G26: 45 | H26: Plano de Produção | I26: COMPONENTE NÃO METÁLICO | J26: PROD MONTAGEM | L26: Rafael | M26: =L26=D26 -> FALSE
A27: 616.673 | B27: 44000002 | C27: ALMEIDA E WERNECK LTDA | D27: Alexandra | E27: Nacional | F27: 30 | G27: 45 | H27: Consumo médio | I27: COMPONENTE NÃO METÁLICO | J27: PROD TRS | L27: Rafael | M27: =L27=D27 -> FALSE
A28: 616.672 | B28: 44000002 | C28: ALMEIDA E WERNECK LTDA | D28: Alexandra | E28: Nacional | F28: 30 | G28: 45 | H28: Consumo médio | I28: COMPONENTE NÃO METÁLICO | J28: PROD TRS | L28: Rafael | M28: =L28=D28 -> FALSE
A29: 616.671 | B29: 44000002 | C29: ALMEIDA E WERNECK LTDA | D29: Alexandra | E29: Nacional | F29: 30 | G29: 45 | H29: Consumo médio | I29: COMPONENTE NÃO METÁLICO | J29: PROD TRS | L29: Rafael | M29: =L29=D29 -> FALSE
A30: 616.670 | B30: 44000002 | C30: ALMEIDA E WERNECK LTDA | D30: Alexandra | E30: Nacional | F30: 30 | G30: 45 | H30: Consumo médio | I30: COMPONENTE NÃO METÁLICO | J30: PROD TRS | L30: Rafael | M30: =L30=D30 -> FALSE
... A51: 212.101 | B51: 44000002 | C51: ALMEIDA E WERNECK LTDA | D51: Alexandra | E51: Nacional | F51: 30 | G51: 45 | H51: Plano de Produção | I51: COMPONENTE NÃO METÁLICO | J51: PROD MONTAGEM | L51: Rafael | M51: =L51=D51 -> FALSE
A52: 305.046 | B52: 44001794 | C52: AMCOR FLEXIBLES BRASIL LTDA | D52: Rafael | E52: Nacional | F52: 30 | G52: 90 | H52: Consumo médio | I52: EMBALAGEM | J52: PROD SALA LIMPA | L52: Gabriela | M52: =L52=D52 -> FALSE
A53: 702928 | B53: 44000950 | C53: APACHE EMBALAGENS PLASTICAS | D53: Alexandra | E53: Nacional | F53: 30 | G53: 90 | H53: Maior entre | I53: SACO PLÁSTICO | J53: PROD PACKING | L53: Gabriela | M53: =L53=D53 -> FALSE
A54: 301.094 | B54: 44000950 | C54: APACHE EMBALAGENS PLASTICAS | D54: Alexandra | E54: Nacional | F54: 30 | G54: 90 | H54: Maior entre | I54: SACO PLÁSTICO | J54: PROD PACKING | L54: Gabriela | M54: =L54=D54 -> FALSE
A55: 301.084 | B55: 44000950 | C55: APACHE EMBALAGENS PLASTICAS | D55: Alexandra | E55: Nacional | F55: 30 | G55: 90 | H55: Maior entre | I55: SACO PLÁSTICO | J55: PROD PACKING | L55: Gabriela | M55: =L55=D55 -> FALSE
A56: 704762 | B56: 44007232 | C56: APM BEVERVANSO PLASTICOS EIRELI | D56: Rafael | E56: Nacional | G56: 0 | H56: NA | I56: PHASE OUT | J56: PROD CLEAR | K56: Mudança de projeto, entrada do Rebranding | L56: Gabriela | M56: =L56=D56 -> FALSE
A57: 204.214 | B57: 44001630 | C57: APTA INDUSTRIA E COMERCIO DE | D57: Alexandra | E57: Nacional | F57: 15 | G57: 90 | H57: Maior entre | I57: POLÍMEROS INJETADOS | J57: PROD INJETORA | L57: Rafael | M57: =L57=D57 -> FALSE
A58: 204.099 | B58: 44001773 | C58: APTA INDUSTRIA E COMERCIO DE | D58: Alexandra | E58: Nacional | F58: 15 | G58: 90 | H58: Plano de Produção | I58: POLÍMEROS INJETADOS | J58: PROD INJETORA | L58: Rafael | M58: =L58=D58 -> FALSE
A59: 204.099 | B59: 44002196 | C59: APTA INDUSTRIA E COMERCIO DE | D59: Alexandra | E59: Nacional | F59: 15 | G59: 90 | H59: Plano de Produção | I59: POLÍMEROS INJETADOS | J59: PROD INJETORA | L59: Rafael | M59: =L59=D59 -> FALSE
A60: 704391 | B60: 44005654 | C60: YLLER BIOMATERIAIS S.A. | D60: Gabriela | E60: Nacional | F60: 30 | G60: 0 | H60: Plano de Produção | I60: EM DESENVOLVIMENTO | J60: PROD RESINA | K60: Material em desenvolvimento, projeto NeoResins com processo não liberado (máquina de misturar Pigmento) - Helo | L60: Gabriela | M60: =L60=D60 -> TRUE
...

Sheet Validade
A1: Pla. | B1: Dep. | C1: Material | D1: Responsável | E1: Origem | F1: Número do material | G1: Lote | H1: Data do vencimento | I1: Data prod. | J1: Utiliz.livre | K1: Nº conta do fornecedor | L1: Tipo | M1: Comentário | N1: Validade
A2: 4400 | B2: 0002 | C2: 202.044 | D2: =INDEX(#REF!,MATCH(Validade!C2,#REF!,0)) -> #REF! | E2: =INDEX(#REF!,MATCH(Validade!C2,#REF!,0)) -> #REF! | F2: ACO INOX 455 D31.75MM | G2: 155224 | H2: 62458 | I2: 42999 | J2: 3060 | L2: =INDEX(Dispodaten2!B:B,MATCH(C2,Dispodaten2!A:A,0)) -> PD
A3: 4400 | B3: 0002 | C3: 205.005 | D3: =INDEX(#REF!,MATCH(Validade!C3,#REF!,0)) -> #REF! | E3: =INDEX(#REF!,MATCH(Validade!C3,#REF!,0)) -> #REF! | F3: ALUMINIO AA6351-T6 D15.8MM | G3: 43909 | H3: 62458 | I3: 43423 | J3: 2900 | L3: =INDEX(Dispodaten2!B:B,MATCH(C3,Dispodaten2!A:A,0)) -> PD
A4: 4400 | B4: 0002 | C4: 212.290 | D4: =INDEX(#REF!,MATCH(Validade!C4,#REF!,0)) -> #REF! | E4: =INDEX(#REF!,MATCH(Validade!C4,#REF!,0)) -> #REF! | F4: BASE EST.CIR.IMP.CON.INTER. | G4: 041724 | H4: 62458 | I4: 43354 | J4: 4 | L4: =INDEX(Dispodaten2!B:B,MATCH(C4,Dispodaten2!A:A,0)) -> PD
A5: 4400 | B5: 0002 | C5: 212.292 | D5: =INDEX(#REF!,MATCH(Validade!C5,#REF!,0)) -> #REF! | E5: =INDEX(#REF!,MATCH(Validade!C5,#REF!,0)) -> #REF! | F5: BASE EST.KIT CIR.NGS FACI. | G5: 027512R02 | H5: 62458 | I5: 43428 | J5: 5 | L5: =INDEX(Dispodaten2!B:B,MATCH(C5,Dispodaten2!A:A,0)) -> PD
A6: 4400 | B6: 0002 | C6: 212.310 | D6: =INDEX(#REF!,MATCH(Validade!C6,#REF!,0)) -> #REF! | E6: =INDEX(#REF!,MATCH(Validade!C6,#REF!,0)) -> #REF! | F6: BASE ESTOJO PARA KIT CIRURGICO GM E WS | G6: 038865 | H6: 62458 | I6: 43298 | J6: 151 | L6: =INDEX(Dispodaten2!B:B,MATCH(C6,Dispodaten2!A:A,0)) -> PD
A7: 4401 | B7: 0002 | C7: 704186 | D7: =INDEX(#REF!,MATCH(Validade!C7,#REF!,0)) -> #REF! | E7: =INDEX(#REF!,MATCH(Validade!C7,#REF!,0)) -> #REF! | F7: EMB TRANSP RESINS G | G7: 154.832 | J7: 1178 | L7: =INDEX(Dispodaten2!B:B,MATCH(C7,Dispodaten2!A:A,0)) -> PD
A8: 4400 | B8: 0001 | C8: 707714 | D8: =INDEX(#REF!,MATCH(Validade!C8,#REF!,0)) -> #REF! | E8: =INDEX(#REF!,MATCH(Validade!C8,#REF!,0)) -> #REF! | F8: EMB. CART. NEOCONVERT PACK COMPONENTES | G8: 156490 | J8: 970 | L8: =INDEX(Dispodaten2!B:B,MATCH(C8,Dispodaten2!A:A,0)) -> PD
A9: 4400 | B9: 0001 | C9: 302.167 | D9: =INDEX(#REF!,MATCH(Validade!C9,#REF!,0)) -> #REF! | E9: =INDEX(#REF!,MATCH(Validade!C9,#REF!,0)) -> #REF! | F9: EMB.CART.IMPL.DEMO.DRIVE GM | G9: 50058 | H9: 62458 | I9: 43230 | J9: 500 | L9: =INDEX(Dispodaten2!B:B,MATCH(C9,Dispodaten2!A:A,0)) -> PD
A10: 4400 | B10: 0002 | C10: 301.094 | D10: =INDEX(#REF!,MATCH(Validade!C10,#REF!,0)) -> #REF! | E10: =INDEX(#REF!,MATCH(Validade!C10,#REF!,0)) -> #REF! | F10: EMB.PRIMARIA PLASTICA 80MM STRAUMANN | G10: 215649 | H10: 62458 | I10: 42878 | J10: 1548000 | L10: =INDEX(Dispodaten2!B:B,MATCH(C10,Dispodaten2!A:A,0)) -> PD
A11: 4400 | B11: 0002 | C11: 519639 | D11: =INDEX(#REF!,MATCH(Validade!C11,#REF!,0)) -> #REF! | E11: =INDEX(#REF!,MATCH(Validade!C11,#REF!,0)) -> #REF! | F11: EQUIPO PARA BOMBA PERISTALTICA | G11: MAI24134LP | J11: 1148 | L11: =INDEX(Dispodaten2!B:B,MATCH(C11,Dispodaten2!A:A,0)) -> V1
A12: 4400 | B12: 0002 | C12: 708001 | D12: =INDEX(#REF!,MATCH(Validade!C12,#REF!,0)) -> #REF! | E12: =INDEX(#REF!,MATCH(Validade!C12,#REF!,0)) -> #REF! | F12: ETIQUETA DE RASTREABILIDADE 11 DIVISOES | G12: 4208 | J12: 9000 | L12: =INDEX(Dispodaten2!B:B,MATCH(C12,Dispodaten2!A:A,0)) -> PD
A13: 4400 | B13: 0002 | C13: 301.092 | D13: =INDEX(#REF!,MATCH(Validade!C13,#REF!,0)) -> #REF! | E13: =INDEX(#REF!,MATCH(Validade!C13,#REF!,0)) -> #REF! | F13: FILM TAPE OPP FTB9030190 | G13: 222566 | H13: 62458 | I13: 43123 | J13: 3040 | L13: =INDEX(Dispodaten2!B:B,MATCH(C13,Dispodaten2!A:A,0)) -> ND
A14: 4400 | B14: 0002 | C14: 212.022 | D14: =INDEX(#REF!,MATCH(Validade!C14,#REF!,0)) -> #REF! | E14: =INDEX(#REF!,MATCH(Validade!C14,#REF!,0)) -> #REF! | F14: INJETADO ABS PARA POSICIONADORES (RHEIN) | G14: 218902 | H14: 62458 | I14: 43000 | J14: 5000 | L14: =INDEX(Dispodaten2!B:B,MATCH(C14,Dispodaten2!A:A,0)) -> PD
A15: 4400 | B15: 0002 | C15: 212.062 | D15: =INDEX(#REF!,MATCH(Validade!C15,#REF!,0)) -> #REF! | E15: =INDEX(#REF!,MATCH(Validade!C15,#REF!,0)) -> #REF! | F15: INJETADO CAPA CALCINAVEL PS P/CLIP AZUL | G15: 146930 | H15: 62458 | I15: 43000 | J15: 181 | L15: =INDEX(Dispodaten2!B:B,MATCH(C15,Dispodaten2!A:A,0)) -> PD
A16: 4400 | B16: 0002 | C16: 212.060 | D16: =INDEX(#REF!,MATCH(Validade!C16,#REF!,0)) -> #REF! | E16: =INDEX(#REF!,MATCH(Validade!C16,#REF!,0)) -> #REF! | F16: INJETADO PS PARA BARRA CLIP AZUL | G16: 166462 | H16: 62458 | I16: 43000 | J16: 94 | L16: =INDEX(Dispodaten2!B:B,MATCH(C16,Dispodaten2!A:A,0)) -> PD
A17: 4400 | B17: 0002 | C17: 210.041 | D17: =INDEX(#REF!,MATCH(Validade!C17,#REF!,0)) -> #REF! | E17: =INDEX(#REF!,MATCH(Validade!C17,#REF!,0)) -> #REF! | F17: METAL DURO D14.0MM | G17: 203111 | H17: 62458 | I17: 43000 | J17: 1245 | L17: =INDEX(Dispodaten2!B:B,MATCH(C17,Dispodaten2!A:A,0)) -> V1
A18: 4400 | B18: 0002 | C18: 210.004 | D18: =INDEX(#REF!,MATCH(Validade!C18,#REF!,0)) -> #REF! | E18: =INDEX(#REF!,MATCH(Validade!C18,#REF!,0)) -> #REF! | F18: METAL DURO D4.20X80MM*** | G18: 153900 | H18: 62458 | I18: 43000 | J18: 52 | L18: =INDEX(Dispodaten2!B:B,MATCH(C18,Dispodaten2!A:A,0)) -> ND
A19: 4400 | B19: 0002 | C19: 210.058 | D19: =INDEX(#REF!,MATCH(Validade!C19,#REF!,0)) -> #REF! | E19: =INDEX(#REF!,MATCH(Validade!C19,#REF!,0)) -> #REF! | F19: METAL DURO D6.0X40MM | G19: 229000 | H19: 62458 | I19: 43429 | J19: 171 | L19: =INDEX(Dispodaten2!B:B,MATCH(C19,Dispodaten2!A:A,0)) -> V1
A20: 4400 | B20: 0002 | C20: 210.060 | D20: =INDEX(#REF!,MATCH(Validade!C20,#REF!,0)) -> #REF! | E20: =INDEX(#REF!,MATCH(Validade!C20,#REF!,0)) -> #REF! | F20: METAL DURO D6.0X50MM | G20: 17830742 | H20: 62458 | I20: 43429 | J20: 300 | L20: =INDEX(Dispodaten2!B:B,MATCH(C20,Dispodaten2!A:A,0)) -> V1
A21: 4400 | B21: 0002 | C21: 212.244 | D21: =INDEX(#REF!,MATCH(Validade!C21,#REF!,0)) -> #REF! | E21: =INDEX(#REF!,MATCH(Validade!C21,#REF!,0)) -> #REF! | F21: MOLA INOX 304 D0.5.EXT.7XPAS.3.5XCP.40MM | G21: 35462 | H21: 62458 | I21: 43000 | J21: 1156 | L21: =INDEX(Dispodaten2!B:B,MATCH(C21,Dispodaten2!A:A,0)) -> PD
A22: 4400 | B22: 0002 | C22: 212.245 | D22: =INDEX(#REF!,MATCH(Validade!C22,#REF!,0)) -> #REF! | E22: =INDEX(#REF!,MATCH(Validade!C22,#REF!,0)) -> #REF! | F22: O-RING SILICONE D10.00X1.00MM VERMELHO | G22: 44337 | H22: 62458 | I22: 43000 | J22: 970 | L22: =INDEX(Dispodaten2!B:B,MATCH(C22,Dispodaten2!A:A,0)) -> PD
A23: 4400 | B23: 0002 | C23: 708381 | D23: =INDEX(#REF!,MATCH(Validade!C23,#REF!,0)) -> #REF! | E23: =INDEX(#REF!,MATCH(Validade!C23,#REF!,0)) -> #REF! | F23: POLI.POM-POLIOXIMETILENO D28.0MM BRANCO | G23: 66612 | J23: 27000 | L23: =INDEX(Dispodaten2!B:B,MATCH(C23,Dispodaten2!A:A,0)) -> PD
A24: 4400 | B24: 0002 | C24: 204.104 | D24: =INDEX(#REF!,MATCH(Validade!C24,#REF!,0)) -> #REF! | E24: =INDEX(#REF!,MATCH(Validade!C24,#REF!,0)) -> #REF! | F24: POLI.POM-POLIOXIMETILENO D50.8MM PRETO | G24: 155995 | H24: 62458 | I24: 43000 | J24: 10000 | L24: =INDEX(Dispodaten2!B:B,MATCH(C24,Dispodaten2!A:A,0)) -> PD
A25: 4400 | B25: 0002 | C25: 203.003 | D25: =INDEX(#REF!,MATCH(Validade!C25,#REF!,0)) -> #REF! | E25: =INDEX(#REF!,MATCH(Validade!C25,#REF!,0)) -> #REF! | F25: TILITE D6.35MM*** | G25: 1003869140 | H25: 62458 | I25: 43000 | J25: 185940 | L25: =INDEX(Dispodaten2!B:B,MATCH(C25,Dispodaten2!A:A,0)) -> ND
A26: 4400 | B26: 0002 | C26: 201.104 | D26: =INDEX(#REF!,MATCH(Validade!C26,#REF!,0)) -> #REF! | E26: =INDEX(#REF!,MATCH(Validade!C26,#REF!,0)) -> #REF! | F26: TITANIO D13MM TI6AL4V-ELI GRAU 5*** | G26: 194332 | H26: 62458 | I26: 43091 | J26: 8600 | L26: =INDEX(Dispodaten2!B:B,MATCH(C26,Dispodaten2!A:A,0)) -> ND
A27: 4400 | B27: 0002 | C27: 201.105 | D27: =INDEX(#REF!,MATCH(Validade!C27,#REF!,0)) -> #REF! | E27: =INDEX(#REF!,MATCH(Validade!C27,#REF!,0)) -> #REF! | F27: TITANIO D16MM TI6AL4V-ELI GRAU 5*** | G27: 194333 | H27: 62458 | I27: 43090 | J27: 8600 | L27: =INDEX(Dispodaten2!B:B,MATCH(C27,Dispodaten2!A:A,0)) -> ND
A28: 4400 | B28: 0002 | C28: 204.047 | D28: =INDEX(#REF!,MATCH(Validade!C28,#REF!,0)) -> #REF! | E28: =INDEX(#REF!,MATCH(Validade!C28,#REF!,0)) -> #REF! | F28: TUBO DE SILICONE D12.0XD6.0MM | G28: 249635 | H28: 62458 | I28: 43000 | J28: 165000 | L28: =INDEX(Dispodaten2!B:B,MATCH(C28,Dispodaten2!A:A,0)) -> PD
A29: 4400 | B29: 0002 | C29: 204.048 | D29: =INDEX(#REF!,MATCH(Validade!C29,#REF!,0)) -> #REF! | E29: =INDEX(#REF!,MATCH(Validade!C29,#REF!,0)) -> #REF! | F29: TUBO DE SILICONE D6.4XD3.2MM | G29: 211503 | H29: 62458 | I29: 43000 | J29: 60000 | L29: =INDEX(Dispodaten2!B:B,MATCH(C29,Dispodaten2!A:A,0)) -> PD
A30: 4400 | B30: 0002 | C30: 204.045 | D30: =INDEX(#REF!,MATCH(Validade!C30,#REF!,0)) -> #REF! | E30: =INDEX(#REF!,MATCH(Validade!C30,#REF!,0)) -> #REF! | F30: TUBO DE SILICONE D8.0XD4.0MM | G30: 252917 | H30: 62458 | I30: 43000 | J30: 75000 | L30: =INDEX(Dispodaten2!B:B,MATCH(C30,Dispodaten2!A:A,0)) -> PD
A31: 4400 | B31: 0002 | C31: 212.104 | D31: =INDEX(#REF!,MATCH(Validade!C31,#REF!,0)) -> #REF! | E31: =INDEX(#REF!,MATCH(Validade!C31,#REF!,0)) -> #REF! | F31: CURETTE SINIO (#1) LONG ALUMINIUM HANDLE | G31: 9973:001 | J31: 79 | K31: A TITAN INSTRUMENTS | L31: =INDEX(Dispodaten2!B:B,MATCH(C31,Dispodaten2!A:A,0)) -> PD | M31: Validade de 4 anos foi arrumada para sem validade
A32: 4400 | B32: 0002 | C32: 212.105 | D32: =INDEX(#REF!,MATCH(Validade!C32,#REF!,0)) -> #REF! | E32: =INDEX(#REF!,MATCH(Validade!C32,#REF!,0)) -> #REF! | F32: CURETTE SINIO (#3) LONG ALUMINIUM HANDLE | G32: 159644:003 | J32: 93 | K32: A TITAN INSTRUMENTS | L32: =INDEX(Dispodaten2!B:B,MATCH(C32,Dispodaten2!A:A,0)) -> PD
A33: 4400 | B33: 0002 | C33: 212.106 | D33: =INDEX(#REF!,MATCH(Validade!C33,#REF!,0)) -> #REF! | E33: =INDEX(#REF!,MATCH(Validade!C33,#REF!,0)) -> #REF! | F33: CURETTE SINIO (#4) LONG ALUMINIUM HANDLE | G33: 159644:002 | J33: 99 | K33: A TITAN INSTRUMENTS | L33: =INDEX(Dispodaten2!B:B,MATCH(C33,Dispodaten2!A:A,0)) -> PD | M33: Validade arrumada como sem validade
A34: 4400 | B34: 0002 | C34: 212.107 | D34: =INDEX(#REF!,MATCH(Validade!C34,#REF!,0)) -> #REF! | E34: =INDEX(#REF!,MATCH(Validade!C34,#REF!,0)) -> #REF! | F34: CURETTE SINIO (#5) LONG ALUMINIUM HANDLE | G34: 159644:001 | J34: 97 | K34: A TITAN INSTRUMENTS | L34: =INDEX(Dispodaten2!B:B,MATCH(C34,Dispodaten2!A:A,0)) -> PD | M34: Sem Validade(Confirmar com fornecedor)
A35: 4400 | B35: 0002 | C35: 212.108 | D35: =INDEX(#REF!,MATCH(Validade!C35,#REF!,0)) -> #REF! | E35: =INDEX(#REF!,MATCH(Validade!C35,#REF!,0)) -> #REF! | F35: CURETTE SINIO (#7) LONG ALUMINIUM HANDLE | G35: 9667:001 | J35: 47 | K35: A TITAN INSTRUMENTS | L35: =INDEX(Dispodaten2!B:B,MATCH(C35,Dispodaten2!A:A,0)) -> PD
A36: 4400 | B36: 0002 | C36: 301.083 | D36: =INDEX(#REF!,MATCH(Validade!C36,#REF!,0)) -> #REF! | E36: =INDEX(#REF!,MATCH(Validade!C36,#REF!,0)) -> #REF! | F36: CONJUNTO EMB.PRIMARIA CURETA TAMPA/BASE | G36: 25 | J36: 385 | K36: ACC COMERCIO DE EMBALAGENS LTDA | L36: =INDEX(Dispodaten2!B:B,MATCH(C36,Dispodaten2!A:A,0)) -> PD
A37: 4400 | B37: 0002 | C37: 301.081 | D37: =INDEX(#REF!,MATCH(Validade!C37,#REF!,0)) -> #REF! | E37: =INDEX(#REF!,MATCH(Validade!C37,#REF!,0)) -> #REF! | F37: EMB PRIMARIA CONJ EMBALAG CHAVES CATRACA | G37: 23 | J37: 3850 | K37: ACC COMERCIO DE EMBALAGENS LTDA | L37: =INDEX(Dispodaten2!B:B,MATCH(C37,Dispodaten2!A:A,0)) -> V1
A38: 4400 | B38: 0002 | C38: 204.246 | D38: =INDEX(#REF!,MATCH(Validade!C38,#REF!,0)) -> #REF! | E38: =INDEX(#REF!,MATCH(Validade!C38,#REF!,0)) -> #REF! | F38: VESTAKEEP DC4420R GRAU ODONT.D6X1000MM | G38: 72451111 | H38: 62458 | J38: 517816 | K38: ACNIS DO BRASIL COMERCIO DE | L38: =INDEX(Dispodaten2!B:B,MATCH(C38,Dispodaten2!A:A,0)) -> PD
A39: 4400 | B39: 0002 | C39: 204.247 | D39: =INDEX(#REF!,MATCH(Validade!C39,#REF!,0)) -> #REF! | E39: =INDEX(#REF!,MATCH(Validade!C39,#REF!,0)) -> #REF! | F39: VESTAKEEP DC4420R GRAU ODONT.D8X1000MM | G39: 72811710 | H39: 62458 | J39: 478733.84 | K39: ACNIS DO BRASIL COMERCIO DE | L39: =INDEX(Dispodaten2!B:B,MATCH(C39,Dispodaten2!A:A,0)) -> PD
A40: 4400 | B40: 0002 | C40: 202.148 | D40: =INDEX(#REF!,MATCH(Validade!C40,#REF!,0)) -> #REF! | E40: =INDEX(#REF!,MATCH(Validade!C40,#REF!,0)) -> #REF! | F40: ACO INOX M340 D12.50MM | G40: CEB957 | H40: 46418 | J40: 292755 | K40: ACOS BOHLER-UDDEHOLM DO BRASIL LTDA | L40: =INDEX(Dispodaten2!B:B,MATCH(C40,Dispodaten2!A:A,0)) -> PD
...

Sheet Dispodaten2
A1: Material | B1: TpM
A2: 506.293 | B2: V1
A3: 102042100606 | B3: V1
A4: 312.147 | B4: V1
A5: 312.085 | B5: V1
A6: 305.046 | B6: V1
A7: 106000 | B7: V1
A8: 702919 | B8: V1
A9: 01.05.0001.9 | B9: V1
A10: 616.1170 | B10: V1
A11: 515782 | B11: V1
A12: 204.143 | B12: V1
... A15: 702907 | B15: V1
A16: 504.022 | B16: V1 | G16: Check
A17: 204.214 | B17: V1 | G17: ✔️
A18: 515.021 | B18: V1 | G18: ✖️
A19: 312.150 | B19: V1
A20: 312.146 | B20: V1
A21: 707368 | B21: V1
A22: 514739 | B22: V1
A23: 704670 | B23: V1
A24: 301.076 | B24: V1
A25: 120 | B25: V1
A26: 803.024 | B26: V1
A27: 805.039 | B27: V1
A28: 608.244 | B28: V1
A29: 616.1390 | B29: V1
A30: 801.235 | B30: V1
... A1217: 314165 | B1217: ND
